***** Running training *****
08/30/2025 22:10:43 - INFO - utils.data_utils -   ***** Running training *****
  Num examples = 11995
08/30/2025 22:10:43 - INFO - utils.data_utils -     Num examples = 11995
  Dataloader size = 11995
08/30/2025 22:10:43 - INFO - utils.data_utils -     Dataloader size = 11995
  Resume training from step 0
08/30/2025 22:10:43 - INFO - utils.data_utils -     Resume training from step 0
  Instantaneous batch size per device = 1
08/30/2025 22:10:43 - INFO - utils.data_utils -     Instantaneous batch size per device = 1
  Total train batch size (w. data & sequence parallel, accumulation) = 12.0
08/30/2025 22:10:43 - INFO - utils.data_utils -     Total train batch size (w. data & sequence parallel, accumulation) = 12.0
  Gradient Accumulation steps = 12
08/30/2025 22:10:43 - INFO - utils.data_utils -     Gradient Accumulation steps = 12
  Total optimization steps per epoch = 300
08/30/2025 22:10:43 - INFO - utils.data_utils -     Total optimization steps per epoch = 300
  Total training parameters per FSDP shard = 11.930383936 B
08/30/2025 22:10:43 - INFO - utils.data_utils -     Total training parameters per FSDP shard = 11.930383936 B
  Master weight dtype: torch.float16
08/30/2025 22:10:43 - INFO - utils.data_utils -     Master weight dtype: torch.float16
Sampling Progress:   0%|                                                                         | 0/16 [01:33<?, ?it/s]
Traceback (most recent call last):                                                               | 0/16 [00:00<?, ?it/s]
  File "/root/miniconda3/envs/aigc_rl/lib/python3.10/site-packages/graphviz/backend/execute.py", line 78, in run_check
    proc = subprocess.run(cmd, **kwargs)
  File "/root/miniconda3/envs/aigc_rl/lib/python3.10/subprocess.py", line 503, in run
    with Popen(*popenargs, **kwargs) as process:
  File "/root/miniconda3/envs/aigc_rl/lib/python3.10/subprocess.py", line 971, in __init__
    self._execute_child(args, executable, preexec_fn, close_fds,
  File "/root/miniconda3/envs/aigc_rl/lib/python3.10/subprocess.py", line 1863, in _execute_child
    raise child_exception_type(errno_num, err_msg, err_filename)
FileNotFoundError: [Errno 2] No such file or directory: PosixPath('dot')

The above exception was the direct cause of the following exception:

Traceback (most recent call last):
  File "/root/miniconda3/envs/aigc_rl/lib/python3.10/runpy.py", line 196, in _run_module_as_main
    return _run_code(code, main_globals, None,
  File "/root/miniconda3/envs/aigc_rl/lib/python3.10/runpy.py", line 86, in _run_code
    exec(code, run_globals)
  File "/root/.vscode-server/extensions/ms-python.debugpy-2025.10.0-linux-x64/bundled/libs/debugpy/adapter/../../debugpy/launcher/../../debugpy/__main__.py", line 71, in <module>
    cli.main()
  File "/root/.vscode-server/extensions/ms-python.debugpy-2025.10.0-linux-x64/bundled/libs/debugpy/adapter/../../debugpy/launcher/../../debugpy/../debugpy/server/cli.py", line 501, in main
    run()
  File "/root/.vscode-server/extensions/ms-python.debugpy-2025.10.0-linux-x64/bundled/libs/debugpy/adapter/../../debugpy/launcher/../../debugpy/../debugpy/server/cli.py", line 351, in run_file
    runpy.run_path(target, run_name="__main__")
  File "/root/.vscode-server/extensions/ms-python.debugpy-2025.10.0-linux-x64/bundled/libs/debugpy/_vendored/pydevd/_pydevd_bundle/pydevd_runpy.py", line 310, in run_path
    return _run_module_code(code, init_globals, run_name, pkg_name=pkg_name, script_name=fname)
  File "/root/.vscode-server/extensions/ms-python.debugpy-2025.10.0-linux-x64/bundled/libs/debugpy/_vendored/pydevd/_pydevd_bundle/pydevd_runpy.py", line 127, in _run_module_code
    _run_code(code, mod_globals, init_globals, mod_name, mod_spec, pkg_name, script_name)
  File "/root/.vscode-server/extensions/ms-python.debugpy-2025.10.0-linux-x64/bundled/libs/debugpy/_vendored/pydevd/_pydevd_bundle/pydevd_runpy.py", line 118, in _run_code
    exec(code, run_globals)
  File "/root/autodl-tmp/DiffusionGRPO/src/train_grpo_flux.py", line 1535, in <module>
    main(args)
  File "/root/autodl-tmp/DiffusionGRPO/src/train_grpo_flux.py", line 1181, in main
    loss, grad_norm = train_one_step(
  File "/root/autodl-tmp/DiffusionGRPO/src/train_grpo_flux.py", line 775, in train_one_step
    rewards, all_latents, all_log_probs, sigma_schedule, all_image_ids, all_condition_latents, all_condition_ids, all_condition_type_ids = sample_reference_model(
  File "/root/autodl-tmp/DiffusionGRPO/src/train_grpo_flux.py", line 604, in sample_reference_model
    z, latents, batch_latents, batch_log_probs, batch_condition_latents, batch_condition_ids, batch_condition_type_ids = run_sample_step(
  File "/root/autodl-tmp/DiffusionGRPO/src/train_grpo_flux.py", line 459, in run_sample_step
    graph_forward.render(filename='/root/autodl-tmp/DiffusionGRPO/visual_results/flux_cmp_graph', view=False, format='png')
  File "/root/miniconda3/envs/aigc_rl/lib/python3.10/site-packages/graphviz/_tools.py", line 185, in wrapper
    return func(*args, **kwargs)
  File "/root/miniconda3/envs/aigc_rl/lib/python3.10/site-packages/graphviz/rendering.py", line 122, in render
    rendered = self._render(*args, **kwargs)
  File "/root/miniconda3/envs/aigc_rl/lib/python3.10/site-packages/graphviz/_tools.py", line 185, in wrapper
    return func(*args, **kwargs)
  File "/root/miniconda3/envs/aigc_rl/lib/python3.10/site-packages/graphviz/backend/rendering.py", line 326, in render
    execute.run_check(cmd,
  File "/root/miniconda3/envs/aigc_rl/lib/python3.10/site-packages/graphviz/backend/execute.py", line 81, in run_check
    raise ExecutableNotFound(cmd) from e
graphviz.backend.execute.ExecutableNotFound: failed to execute PosixPath('dot'), make sure the Graphviz executables are on your systems' PATH
[rank0]: Traceback (most recent call last):
[rank0]:   File "/root/miniconda3/envs/aigc_rl/lib/python3.10/site-packages/graphviz/backend/execute.py", line 78, in run_check
[rank0]:     proc = subprocess.run(cmd, **kwargs)
[rank0]:   File "/root/miniconda3/envs/aigc_rl/lib/python3.10/subprocess.py", line 503, in run
[rank0]:     with Popen(*popenargs, **kwargs) as process:
[rank0]:   File "/root/miniconda3/envs/aigc_rl/lib/python3.10/subprocess.py", line 971, in __init__
[rank0]:     self._execute_child(args, executable, preexec_fn, close_fds,
[rank0]:   File "/root/miniconda3/envs/aigc_rl/lib/python3.10/subprocess.py", line 1863, in _execute_child
[rank0]:     raise child_exception_type(errno_num, err_msg, err_filename)
[rank0]: FileNotFoundError: [Errno 2] No such file or directory: PosixPath('dot')

[rank0]: The above exception was the direct cause of the following exception:

[rank0]: Traceback (most recent call last):
[rank0]:   File "/root/miniconda3/envs/aigc_rl/lib/python3.10/runpy.py", line 196, in _run_module_as_main
[rank0]:     return _run_code(code, main_globals, None,
[rank0]:   File "/root/miniconda3/envs/aigc_rl/lib/python3.10/runpy.py", line 86, in _run_code
[rank0]:     exec(code, run_globals)
[rank0]:   File "/root/.vscode-server/extensions/ms-python.debugpy-2025.10.0-linux-x64/bundled/libs/debugpy/adapter/../../debugpy/launcher/../../debugpy/__main__.py", line 71, in <module>
[rank0]:     cli.main()
[rank0]:   File "/root/.vscode-server/extensions/ms-python.debugpy-2025.10.0-linux-x64/bundled/libs/debugpy/adapter/../../debugpy/launcher/../../debugpy/../debugpy/server/cli.py", line 501, in main
[rank0]:     run()
[rank0]:   File "/root/.vscode-server/extensions/ms-python.debugpy-2025.10.0-linux-x64/bundled/libs/debugpy/adapter/../../debugpy/launcher/../../debugpy/../debugpy/server/cli.py", line 351, in run_file
[rank0]:     runpy.run_path(target, run_name="__main__")
[rank0]:   File "/root/.vscode-server/extensions/ms-python.debugpy-2025.10.0-linux-x64/bundled/libs/debugpy/_vendored/pydevd/_pydevd_bundle/pydevd_runpy.py", line 310, in run_path
[rank0]:     return _run_module_code(code, init_globals, run_name, pkg_name=pkg_name, script_name=fname)
[rank0]:   File "/root/.vscode-server/extensions/ms-python.debugpy-2025.10.0-linux-x64/bundled/libs/debugpy/_vendored/pydevd/_pydevd_bundle/pydevd_runpy.py", line 127, in _run_module_code
[rank0]:     _run_code(code, mod_globals, init_globals, mod_name, mod_spec, pkg_name, script_name)
[rank0]:   File "/root/.vscode-server/extensions/ms-python.debugpy-2025.10.0-linux-x64/bundled/libs/debugpy/_vendored/pydevd/_pydevd_bundle/pydevd_runpy.py", line 118, in _run_code
[rank0]:     exec(code, run_globals)
[rank0]:   File "/root/autodl-tmp/DiffusionGRPO/src/train_grpo_flux.py", line 1535, in <module>
[rank0]:     main(args)
[rank0]:   File "/root/autodl-tmp/DiffusionGRPO/src/train_grpo_flux.py", line 1181, in main
[rank0]:     loss, grad_norm = train_one_step(
[rank0]:   File "/root/autodl-tmp/DiffusionGRPO/src/train_grpo_flux.py", line 775, in train_one_step
[rank0]:     rewards, all_latents, all_log_probs, sigma_schedule, all_image_ids, all_condition_latents, all_condition_ids, all_condition_type_ids = sample_reference_model(
[rank0]:   File "/root/autodl-tmp/DiffusionGRPO/src/train_grpo_flux.py", line 604, in sample_reference_model
[rank0]:     z, latents, batch_latents, batch_log_probs, batch_condition_latents, batch_condition_ids, batch_condition_type_ids = run_sample_step(
[rank0]:   File "/root/autodl-tmp/DiffusionGRPO/src/train_grpo_flux.py", line 459, in run_sample_step
[rank0]:     graph_forward.render(filename='/root/autodl-tmp/DiffusionGRPO/visual_results/flux_cmp_graph', view=False, format='png')
[rank0]:   File "/root/miniconda3/envs/aigc_rl/lib/python3.10/site-packages/graphviz/_tools.py", line 185, in wrapper
[rank0]:     return func(*args, **kwargs)
[rank0]:   File "/root/miniconda3/envs/aigc_rl/lib/python3.10/site-packages/graphviz/rendering.py", line 122, in render
[rank0]:     rendered = self._render(*args, **kwargs)
[rank0]:   File "/root/miniconda3/envs/aigc_rl/lib/python3.10/site-packages/graphviz/_tools.py", line 185, in wrapper
[rank0]:     return func(*args, **kwargs)
[rank0]:   File "/root/miniconda3/envs/aigc_rl/lib/python3.10/site-packages/graphviz/backend/rendering.py", line 326, in render
[rank0]:     execute.run_check(cmd,
[rank0]:   File "/root/miniconda3/envs/aigc_rl/lib/python3.10/site-packages/graphviz/backend/execute.py", line 81, in run_check
[rank0]:     raise ExecutableNotFound(cmd) from e
[rank0]: graphviz.backend.execute.ExecutableNotFound: failed to execute PosixPath('dot'), make sure the Graphviz executables are on your systems' PATH
