***** Running training *****
08/25/2025 01:54:56 - INFO - utils.data_utils -   ***** Running training *****
  Num examples = 11995
08/25/2025 01:54:56 - INFO - utils.data_utils -     Num examples = 11995
  Dataloader size = 1500
08/25/2025 01:54:56 - INFO - utils.data_utils -     Dataloader size = 1500
  Resume training from step 0
08/25/2025 01:54:56 - INFO - utils.data_utils -     Resume training from step 0
  Instantaneous batch size per device = 1
08/25/2025 01:54:56 - INFO - utils.data_utils -     Instantaneous batch size per device = 1
  Total train batch size (w. data & sequence parallel, accumulation) = 32.0
08/25/2025 01:54:56 - INFO - utils.data_utils -     Total train batch size (w. data & sequence parallel, accumulation) = 32.0
  Gradient Accumulation steps = 4
08/25/2025 01:54:56 - INFO - utils.data_utils -     Gradient Accumulation steps = 4
  Total optimization steps per epoch = 300
08/25/2025 01:54:56 - INFO - utils.data_utils -     Total optimization steps per epoch = 300
  Total training parameters per FSDP shard = 1.48767604 B
08/25/2025 01:54:56 - INFO - utils.data_utils -     Total training parameters per FSDP shard = 1.48767604 B
  Master weight dtype: torch.bfloat16
08/25/2025 01:54:56 - INFO - utils.data_utils -     Master weight dtype: torch.bfloat16
Sampling Progress: 100%|████████████████████████████████████████████████████████████████████████████████████████████████████████████████████████████████| 16/16 [00:29<00:00,  1.85s/it]
08/25/2025 01:55:26 - INFO - utils.data_utils -   --> decode image and save to log dir...███████████████████████████████████████████████████████████████| 16/16 [00:29<00:00,  1.31s/it]
--> decode image and save to log dir...
Traceback (most recent call last):
  File "/root/miniconda3/envs/aigc_rl/lib/python3.10/site-packages/PIL/ImageFile.py", line 644, in _save
    fh = fp.fileno()
AttributeError: '_idat' object has no attribute 'fileno'

During handling of the above exception, another exception occurred:

Traceback (most recent call last):
  File "/root/autodl-tmp/DiffusionGRPO/src/train_grpo_flux.py", line 1455, in <module>
    main(args)
  File "/root/autodl-tmp/DiffusionGRPO/src/train_grpo_flux.py", line 1101, in main
    loss, grad_norm = train_one_step(
  File "/root/autodl-tmp/DiffusionGRPO/src/train_grpo_flux.py", line 712, in train_one_step
    rewards, all_latents, all_log_probs, sigma_schedule, all_image_ids, all_condition_latents, all_condition_ids, all_condition_type_ids = sample_reference_model(
  File "/root/autodl-tmp/DiffusionGRPO/src/train_grpo_flux.py", line 586, in sample_reference_model
    decoded_image[0].save(os.path.join(sample_save_path, f"image_{index}.png"))
  File "/root/miniconda3/envs/aigc_rl/lib/python3.10/site-packages/PIL/Image.py", line 2588, in save
    save_handler(self, fp, filename)
  File "/root/miniconda3/envs/aigc_rl/lib/python3.10/site-packages/PIL/PngImagePlugin.py", line 1495, in _save
    ImageFile._save(
  File "/root/miniconda3/envs/aigc_rl/lib/python3.10/site-packages/PIL/ImageFile.py", line 648, in _save
    _encode_tile(im, fp, tile, bufsize, None, exc)
  File "/root/miniconda3/envs/aigc_rl/lib/python3.10/site-packages/PIL/ImageFile.py", line 674, in _encode_tile
    errcode, data = encoder.encode(bufsize)[1:]
KeyboardInterrupt
[rank0]: Traceback (most recent call last):
[rank0]:   File "/root/miniconda3/envs/aigc_rl/lib/python3.10/site-packages/PIL/ImageFile.py", line 644, in _save
[rank0]:     fh = fp.fileno()
[rank0]: AttributeError: '_idat' object has no attribute 'fileno'

[rank0]: During handling of the above exception, another exception occurred:

[rank0]: Traceback (most recent call last):
[rank0]:   File "/root/autodl-tmp/DiffusionGRPO/src/train_grpo_flux.py", line 1455, in <module>
[rank0]:     main(args)
[rank0]:   File "/root/autodl-tmp/DiffusionGRPO/src/train_grpo_flux.py", line 1101, in main
[rank0]:     loss, grad_norm = train_one_step(
[rank0]:   File "/root/autodl-tmp/DiffusionGRPO/src/train_grpo_flux.py", line 712, in train_one_step
[rank0]:     rewards, all_latents, all_log_probs, sigma_schedule, all_image_ids, all_condition_latents, all_condition_ids, all_condition_type_ids = sample_reference_model(
[rank0]:   File "/root/autodl-tmp/DiffusionGRPO/src/train_grpo_flux.py", line 586, in sample_reference_model
[rank0]:     decoded_image[0].save(os.path.join(sample_save_path, f"image_{index}.png"))
[rank0]:   File "/root/miniconda3/envs/aigc_rl/lib/python3.10/site-packages/PIL/Image.py", line 2588, in save
[rank0]:     save_handler(self, fp, filename)
[rank0]:   File "/root/miniconda3/envs/aigc_rl/lib/python3.10/site-packages/PIL/PngImagePlugin.py", line 1495, in _save
[rank0]:     ImageFile._save(
[rank0]:   File "/root/miniconda3/envs/aigc_rl/lib/python3.10/site-packages/PIL/ImageFile.py", line 648, in _save
[rank0]:     _encode_tile(im, fp, tile, bufsize, None, exc)
[rank0]:   File "/root/miniconda3/envs/aigc_rl/lib/python3.10/site-packages/PIL/ImageFile.py", line 674, in _encode_tile
[rank0]:     errcode, data = encoder.encode(bufsize)[1:]
[rank0]: KeyboardInterrupt
